<?xml version="1.0"?>
<robot name="simple_robot">

  <!-- ================= base_link ================= -->
  <link name="base_link">
    <visual>
      <geometry>
        <box size="0.4 0.3 0.1"/>
      </geometry>
      <material name="blue">
        <color rgba="0 0 1 1"/>
      </material>
    </visual>
  </link>

  <!-- ================= 左轮 ================= -->
  <link name="wheel_left_link">
    <visual>
      <origin xyz="0 0 0" rpy="1.57 0 0"/> <!-- 关键：旋转 -->
      <geometry>
        <cylinder radius="0.05" length="0.02"/>
      </geometry>
      <material name="black">
        <color rgba="0 0 0 1"/>
      </material>
    </visual>
  </link>

  <joint name="wheel_left_joint" type="revolute">
    <parent link="base_link"/>
    <child link="wheel_left_link"/>
    <origin xyz="0 0.15 -0.05" rpy="0 0 0"/>
    <axis xyz="0 1 0"/>
    <limit lower="-3.14" upper="3.14" effort="10" velocity="10"/>
  </joint>

  <!-- ================= 右轮 ================= -->
  <link name="wheel_right_link">
    <visual>
      <origin xyz="0 0 0" rpy="1.57 0 0"/> <!-- 同样旋转 -->
      <geometry>
        <cylinder radius="0.05" length="0.02"/>
      </geometry>
      <material name="black">
        <color rgba="0 0 0 1"/>
      </material>
    </visual>
  </link>

  <joint name="wheel_right_joint" type="revolute">
    <parent link="base_link"/>
    <child link="wheel_right_link"/>
    <origin xyz="0 -0.15 -0.05" rpy="0 0 0"/>
    <axis xyz="0 1 0"/>
    <limit lower="-3.14" upper="3.14" effort="10" velocity="10"/>
  </joint>

  <!-- ================= 万向轮 ================= -->
  <link name="caster_link">
    <visual>
      <geometry>
        <sphere radius="0.04"/>
      </geometry>
      <material name="gray">
        <color rgba="0.5 0.5 0.5 1"/>
      </material>
    </visual>
  </link>

  <joint name="caster_joint" type="fixed">
    <parent link="base_link"/>
    <child link="caster_link"/>
    <origin xyz="-0.15 0 -0.05" rpy="0 0 0"/>
  </joint>

</robot>
